Workbook

Sheet Overview
A2: Galicia options: what the data says
A4: 21 Aug–16 Sep 2026. October expiry. ARS per share unless stated. Historical estimates, not executable quotes.
A6: Latest date | B6: GGAL spot | C6: ATM strike | D6: ATM IV | E6: 20-day RV | F6: IV / RV20
A7: ='Daily volatility'!A25 -> 46281 | B7: ='Daily volatility'!B25 -> 6760 | C7: ='Daily volatility'!C25 -> 6800 | D7: ='Daily volatility'!F25 -> 0.43336755 | E7: ='Daily volatility'!H25 -> 0.29834284 | F7: ='Daily volatility'!K25 -> 1.4525824
A10: Coverage | B10: 920 observations, 50 series, 19 dates. Calls and puts share one expiry.
A11: Closing-price problem | B11: The added Closing price column refers to next-row openingPrice. It is excluded.
A12: Data screening | B12: 658 IV estimates retained. Zero-volume and inconsistent-range rows are excluded.
A13: Model uncertainty | B13: 30% continuous rate and zero dividends are assumptions. Daily table includes 20% / 40% rate checks.
A14: Put/call ratio | B14: Raw-volume ratio measures this file only. Volume units and market-wide coverage are unverified.
A15: Strategy use | B15: Compare historical costs and payoff shapes. Negative butterfly costs are data flags, not proven arbitrage.
A16: Missing context | B16: No bid/ask, OI or second expiry. Nineteen dates cannot support a 1-year IV rank.
A20: Date | B20: ATM IV | C20: 20-day RV
A21: =TEXT('Daily volatility'!A7,"dd-mmm") -> 21-ago | B21: ='Daily volatility'!F7 -> 0.46627794 | C21: ='Daily volatility'!H7 -> 0.30430091
A22: =TEXT('Daily volatility'!A8,"dd-mmm") -> 24-ago | B22: ='Daily volatility'!F8 -> 0.44626193 | C22: ='Daily volatility'!H8 -> 0.36708143
A23: =TEXT('Daily volatility'!A9,"dd-mmm") -> 25-ago | B23: ='Daily volatility'!F9 -> 0.4152837 | C23: ='Daily volatility'!H9 -> 0.37334688
A24: =TEXT('Daily volatility'!A10,"dd-mmm") -> 26-ago | B24: ='Daily volatility'!F10 -> 0.41015452 | C24: ='Daily volatility'!H10 -> 0.37235223
A25: =TEXT('Daily volatility'!A11,"dd-mmm") -> 27-ago | B25: ='Daily volatility'!F11 -> 0.42210478 | C25: ='Daily volatility'!H11 -> 0.37793027
A26: =TEXT('Daily volatility'!A12,"dd-mmm") -> 28-ago | B26: ='Daily volatility'!F12 -> 0.41442294 | C26: ='Daily volatility'!H12 -> 0.35592248
A27: =TEXT('Daily volatility'!A13,"dd-mmm") -> 31-ago | B27: ='Daily volatility'!F13 -> 0.43406968 | C27: ='Daily volatility'!H13 -> 0.3788277
A28: =TEXT('Daily volatility'!A14,"dd-mmm") -> 01-sep | B28: ='Daily volatility'!F14 -> 0.43289966 | C28: ='Daily volatility'!H14 -> 0.3769853
A29: =TEXT('Daily volatility'!A15,"dd-mmm") -> 02-sep | B29: ='Daily volatility'!F15 -> 0.42512126 | C29: ='Daily volatility'!H15 -> 0.37387495
A30: =TEXT('Daily volatility'!A16,"dd-mmm") -> 03-sep | B30: ='Daily volatility'!F16 -> 0.42328256 | C30: ='Daily volatility'!H16 -> 0.37398562
A31: =TEXT('Daily volatility'!A17,"dd-mmm") -> 04-sep | B31: ='Daily volatility'!F17 -> 0.41549357 | C31: ='Daily volatility'!H17 -> 0.35609757
A32: =TEXT('Daily volatility'!A18,"dd-mmm") -> 07-sep | B32: ='Daily volatility'!F18 -> 0.42889257 | C32: ='Daily volatility'!H18 -> 0.35655003
... A39: =TEXT('Daily volatility'!A25,"dd-mmm") -> 16-sep | B39: ='Daily volatility'!F25 -> 0.43336755 | C39: ='Daily volatility'!H25 -> 0.29834284
A43: Quality check | B43: Count
A44: Zero reported volume | B44: 88
A45: Price outside range | B45: 120
A46: Below intrinsic | B46: 68
A47: Model-bound failure | B47: 54
A48: Duplicate date / ticker | B48: 0
A50: Quality counts overlap. Screened prices can still be stale or asynchronous.
A53: How to read the measures
A55: IV vs. RV | B55: IV describes model-implied future uncertainty; RV measures past share-price variability.
A57: Butterfly | B57: Buy the two wings and sell two middle-strike options. Peak expiration P&L is at the middle strike.
A59: 1x2 ratio | B59: Buy one option and sell two further out-of-the-money options. Premium income adds tail exposure.
A65: Example: 6,600 / 6,800 / 7,000 call butterfly
A66: 16 Sep prices. Buy 1 call at 6,600, sell 2 at 6,800, buy 1 at 7,000. All expiration outcomes exclude costs.
A68: Debit / share | B68: Max profit / share | C68: Max loss / share | D68: Lower breakeven | E68: Upper breakeven | F68: Debit / 100 shares
A69: =Strategies!J7 -> 15.01 | B69: =Strategies!L7 -> 184.99 | C69: =Strategies!M7 -> 15.01 | D69: =Strategies!N7 -> 6615.01 | E69: =Strategies!O7 -> 6984.99 | F69: =Strategies!Q7 -> 1501
...

Sheet Daily volatility
A2: Daily volatility and market ratios
A4: P/C volume uses the raw API field. IV uses the same October expiry each day, not a constant-maturity series.
A6: Date | B6: GGAL spot | C6: ATM strike | D6: Call IV | E6: Put IV | F6: ATM IV avg | G6: RV 10d | H6: RV 20d | I6: RV 60d | J6: IV − RV20 | K6: IV / RV20 | L6: P/C IV | M6: Call raw volume | N6: Put raw volume | O6: P/C raw volume | P6: 25d call IV | Q6: 25d put IV | R6: 25d skew | S6: Vol butterfly | T6: IV at 20% rate | U6: IV at 40% rate | V6: Valid IV rows
A7: 46255 | B7: 6620 | C7: 6600 | D7: 0.4503744 | E7: 0.48218149 | F7: 0.46627794 | G7: 0.32282221 | H7: 0.30430091 | J7: =IF(F7="","n.a.",F7-H7) -> 0.16197703 | K7: =IF(F7="","n.a.",F7/H7) -> 1.5322923 | L7: =IF(D7="","n.a.",E7/D7) -> 1.0706237 | M7: =SUMIFS('IV history'!$N$7:$N$926,'IV history'!$A$7:$A$926,A7,'IV history'!$C$7:$C$926,"call") -> 1.0705902e+09 | N7: =SUMIFS('IV history'!$N$7:$N$926,'IV history'!$A$7:$A$926,A7,'IV history'!$C$7:$C$926,"put") -> 3.8548392e+08 | O7: =IF(M7=0,"n.a.",N7/M7) -> 0.36006675 | P7: 0.44361666 | Q7: 0.46679113 | R7: =IF(OR(P7="",Q7=""),"n.a.",Q7-P7) -> 0.023174478 | S7: =IF(OR(P7="",Q7="",F7=""),"n.a.",(P7+Q7)/2-F7) -> -0.011074046 | T7: 0.47717652 | U7: 0.45077854 | V7: 31
A8: 46258 | B8: 6950 | C8: 7000 | D8: 0.42841322 | E8: 0.46411065 | F8: 0.44626193 | G8: 0.44037522 | H8: 0.36708143 | J8: =IF(F8="","n.a.",F8-H8) -> 0.079180506 | K8: =IF(F8="","n.a.",F8/H8) -> 1.2157028 | L8: =IF(D8="","n.a.",E8/D8) -> 1.0833248 | M8: =SUMIFS('IV history'!$N$7:$N$926,'IV history'!$A$7:$A$926,A8,'IV history'!$C$7:$C$926,"call") -> 3.6754384e+09 | N8: =SUMIFS('IV history'!$N$7:$N$926,'IV history'!$A$7:$A$926,A8,'IV history'!$C$7:$C$926,"put") -> 1.7203605e+09 | O8: =IF(M8=0,"n.a.",N8/M8) -> 0.46806948 | P8: 0.42823892 | Q8: 0.46651876 | R8: =IF(OR(P8="",Q8=""),"n.a.",Q8-P8) -> 0.038279838 | S8: =IF(OR(P8="",Q8="",F8=""),"n.a.",(P8+Q8)/2-F8) -> 0.0011169024 | T8: 0.45550845 | U8: 0.43283677 | V8: 34
A9: 46259 | B9: 7075 | C9: 7000 | D9: 0.37980973 | E9: 0.45075767 | F9: 0.4152837 | G9: 0.45248561 | H9: 0.37334688 | J9: =IF(F9="","n.a.",F9-H9) -> 0.041936826 | K9: =IF(F9="","n.a.",F9/H9) -> 1.1123267 | L9: =IF(D9="","n.a.",E9/D9) -> 1.1867986 | M9: =SUMIFS('IV history'!$N$7:$N$926,'IV history'!$A$7:$A$926,A9,'IV history'!$C$7:$C$926,"call") -> 2.7577191e+09 | N9: =SUMIFS('IV history'!$N$7:$N$926,'IV history'!$A$7:$A$926,A9,'IV history'!$C$7:$C$926,"put") -> 907131131 | O9: =IF(M9=0,"n.a.",N9/M9) -> 0.32894254 | P9: 0.4120431 | Q9: 0.45138373 | R9: =IF(OR(P9="",Q9=""),"n.a.",Q9-P9) -> 0.039340631 | S9: =IF(OR(P9="",Q9="",F9=""),"n.a.",(P9+Q9)/2-F9) -> 0.016429712 | T9: 0.42859688 | U9: 0.39586637 | V9: 34
A10: 46260 | B10: 7045 | C10: 7000 | D10: 0.36729783 | E10: 0.45301122 | F10: 0.41015452 | G10: 0.39051326 | H10: 0.37235223 | J10: =IF(F10="","n.a.",F10-H10) -> 0.037802291 | K10: =IF(F10="","n.a.",F10/H10) -> 1.1015229 | L10: =IF(D10="","n.a.",E10/D10) -> 1.2333621 | M10: =SUMIFS('IV history'!$N$7:$N$926,'IV history'!$A$7:$A$926,A10,'IV history'!$C$7:$C$926,"call") -> 2.0727826e+09 | N10: =SUMIFS('IV history'!$N$7:$N$926,'IV history'!$A$7:$A$926,A10,'IV history'!$C$7:$C$926,"put") -> 6.9325327e+08 | O10: =IF(M10=0,"n.a.",N10/M10) -> 0.33445536 | P10: 0.41021052 | Q10: 0.45375423 | R10: =IF(OR(P10="",Q10=""),"n.a.",Q10-P10) -> 0.043543707 | S10: =IF(OR(P10="",Q10="",F10=""),"n.a.",(P10+Q10)/2-F10) -> 0.02182785 | T10: 0.42267352 | U10: 0.39169758 | V10: 35
A11: 46261 | B11: 6880 | C11: 6800 | D11: 0.38954597 | E11: 0.45466358 | F11: 0.42210478 | G11: 0.40861851 | H11: 0.37793027 | I11: 0.43844102 | J11: =IF(F11="","n.a.",F11-H11) -> 0.044174503 | K11: =IF(F11="","n.a.",F11/H11) -> 1.1168853 | L11: =IF(D11="","n.a.",E11/D11) -> 1.1671628 | M11: =SUMIFS('IV history'!$N$7:$N$926,'IV history'!$A$7:$A$926,A11,'IV history'!$C$7:$C$926,"call") -> 2.4476718e+09 | N11: =SUMIFS('IV history'!$N$7:$N$926,'IV history'!$A$7:$A$926,A11,'IV history'!$C$7:$C$926,"put") -> 8.6417165e+08 | O11: =IF(M11=0,"n.a.",N11/M11) -> 0.35305863 | P11: 0.41036126 | Q11: 0.45239012 | R11: =IF(OR(P11="",Q11=""),"n.a.",Q11-P11) -> 0.042028859 | S11: =IF(OR(P11="",Q11="",F11=""),"n.a.",(P11+Q11)/2-F11) -> 0.0092709125 | T11: 0.43503069 | U11: 0.40353587 | V11: 37
A12: 46262 | B12: 6810 | C12: 6800 | D12: 0.38728894 | E12: 0.44155693 | F12: 0.41442294 | G12: 0.40393696 | H12: 0.35592248 | I12: 0.43864432 | J12: =IF(F12="","n.a.",F12-H12) -> 0.058500454 | K12: =IF(F12="","n.a.",F12/H12) -> 1.1643629 | L12: =IF(D12="","n.a.",E12/D12) -> 1.1401227 | M12: =SUMIFS('IV history'!$N$7:$N$926,'IV history'!$A$7:$A$926,A12,'IV history'!$C$7:$C$926,"call") -> 1.7405878e+09 | N12: =SUMIFS('IV history'!$N$7:$N$926,'IV history'!$A$7:$A$926,A12,'IV history'!$C$7:$C$926,"put") -> 1.0211673e+09 | O12: =IF(M12=0,"n.a.",N12/M12) -> 0.58667959 | P12: 0.40920858 | Q12: 0.44212028 | R12: =IF(OR(P12="",Q12=""),"n.a.",Q12-P12) -> 0.032911696 | S12: =IF(OR(P12="",Q12="",F12=""),"n.a.",(P12+Q12)/2-F12) -> 0.011241494 | T12: 0.42537899 | U12: 0.39864621 | V12: 34
A13: 46265 | B13: 7015 | C13: 7000 | D13: 0.41152443 | E13: 0.45661493 | F13: 0.43406968 | G13: 0.39539428 | H13: 0.3788277 | I13: 0.4388705 | J13: =IF(F13="","n.a.",F13-H13) -> 0.055241975 | K13: =IF(F13="","n.a.",F13/H13) -> 1.1458235 | L13: =IF(D13="","n.a.",E13/D13) -> 1.1095695 | M13: =SUMIFS('IV history'!$N$7:$N$926,'IV history'!$A$7:$A$926,A13,'IV history'!$C$7:$C$926,"call") -> 2837380990 | N13: =SUMIFS('IV history'!$N$7:$N$926,'IV history'!$A$7:$A$926,A13,'IV history'!$C$7:$C$926,"put") -> 7.5490269e+08 | O13: =IF(M13=0,"n.a.",N13/M13) -> 0.26605616 | P13: 0.41895923 | Q13: 0.45887837 | R13: =IF(OR(P13="",Q13=""),"n.a.",Q13-P13) -> 0.03991914 | S13: =IF(OR(P13="",Q13="",F13=""),"n.a.",(P13+Q13)/2-F13) -> 0.0048491232 | T13: 0.44411373 | U13: 0.4199053 | V13: 35
A14: 46266 | B14: 7060 | C14: 7000 | D14: 0.3990126 | E14: 0.46678672 | F14: 0.43289966 | G14: 0.3527892 | H14: 0.3769853 | I14: 0.43911418 | J14: =IF(F14="","n.a.",F14-H14) -> 0.055914361 | K14: =IF(F14="","n.a.",F14/H14) -> 1.1483197 | L14: =IF(D14="","n.a.",E14/D14) -> 1.1698546 | M14: =SUMIFS('IV history'!$N$7:$N$926,'IV history'!$A$7:$A$926,A14,'IV history'!$C$7:$C$926,"call") -> 3640294763 | N14: =SUMIFS('IV history'!$N$7:$N$926,'IV history'!$A$7:$A$926,A14,'IV history'!$C$7:$C$926,"put") -> 7.4706757e+08 | O14: =IF(M14=0,"n.a.",N14/M14) -> 0.20522172 | P14: 0.41483887 | Q14: 0.46070565 | R14: =IF(OR(P14="",Q14=""),"n.a.",Q14-P14) -> 0.045866783 | S14: =IF(OR(P14="",Q14="",F14=""),"n.a.",(P14+Q14)/2-F14) -> 0.0048726016 | T14: 0.44405228 | U14: 0.41718277 | V14: 35
A15: 46267 | B15: 7170 | C15: 7200 | D15: 0.39360067 | E15: 0.45664186 | F15: 0.42512126 | G15: 0.33443184 | H15: 0.37387495 | I15: 0.43872123 | J15: =IF(F15="","n.a.",F15-H15) -> 0.05124631 | K15: =IF(F15="","n.a.",F15/H15) -> 1.137068 | L15: =IF(D15="","n.a.",E15/D15) -> 1.1601654 | M15: =SUMIFS('IV history'!$N$7:$N$926,'IV history'!$A$7:$A$926,A15,'IV history'!$C$7:$C$926,"call") -> 2.6939953e+09 | N15: =SUMIFS('IV history'!$N$7:$N$926,'IV history'!$A$7:$A$926,A15,'IV history'!$C$7:$C$926,"put") -> 6.919505e+08 | O15: =IF(M15=0,"n.a.",N15/M15) -> 0.25684918 | P15: 0.40423199 | Q15: 0.45854063 | R15: =IF(OR(P15="",Q15=""),"n.a.",Q15-P15) -> 0.054308645 | S15: =IF(OR(P15="",Q15="",F15=""),"n.a.",(P15+Q15)/2-F15) -> 0.0062650487 | T15: 0.433909 | U15: 0.4124856 | V15: 34
A16: 46268 | B16: 7075 | C16: 7000 | D16: 0.38797271 | E16: 0.45859241 | F16: 0.42328256 | G16: 0.34624524 | H16: 0.37398562 | I16: 0.43780104 | J16: =IF(F16="","n.a.",F16-H16) -> 0.049296938 | K16: =IF(F16="","n.a.",F16/H16) -> 1.1318151 | L16: =IF(D16="","n.a.",E16/D16) -> 1.1820223 | M16: =SUMIFS('IV history'!$N$7:$N$926,'IV history'!$A$7:$A$926,A16,'IV history'!$C$7:$C$926,"call") -> 3.6394143e+09 | N16: =SUMIFS('IV history'!$N$7:$N$926,'IV history'!$A$7:$A$926,A16,'IV history'!$C$7:$C$926,"put") -> 9.4090421e+08 | O16: =IF(M16=0,"n.a.",N16/M16) -> 0.25853177 | P16: 0.41161777 | Q16: 0.45768114 | R16: =IF(OR(P16="",Q16=""),"n.a.",Q16-P16) -> 0.046063372 | S16: =IF(OR(P16="",Q16="",F16=""),"n.a.",(P16+Q16)/2-F16) -> 0.011366898 | T16: 0.43480202 | U16: 0.40708164 | V16: 36
A17: 46269 | B17: 7005 | C17: 7000 | D17: 0.39497486 | E17: 0.43601228 | F17: 0.41549357 | G17: 0.35438455 | H17: 0.35609757 | I17: 0.43422892 | J17: =IF(F17="","n.a.",F17-H17) -> 0.059396002 | K17: =IF(F17="","n.a.",F17/H17) -> 1.166797 | L17: =IF(D17="","n.a.",E17/D17) -> 1.1038988 | M17: =SUMIFS('IV history'!$N$7:$N$926,'IV history'!$A$7:$A$926,A17,'IV history'!$C$7:$C$926,"call") -> 1.8612115e+09 | N17: =SUMIFS('IV history'!$N$7:$N$926,'IV history'!$A$7:$A$926,A17,'IV history'!$C$7:$C$926,"put") -> 4.7550423e+08 | O17: =IF(M17=0,"n.a.",N17/M17) -> 0.25548103 | P17: 0.40887654 | Q17: 0.43863357 | R17: =IF(OR(P17="",Q17=""),"n.a.",Q17-P17) -> 0.02975703 | S17: =IF(OR(P17="",Q17="",F17=""),"n.a.",(P17+Q17)/2-F17) -> 0.0082614824 | T17: 0.42503132 | U17: 0.40209519 | V17: 34
A18: 46272 | B18: 6935 | C18: 7000 | D18: 0.42273407 | E18: 0.43505107 | F18: 0.42889257 | G18: 0.26661964 | H18: 0.35655003 | I18: 0.43438604 | J18: =IF(F18="","n.a.",F18-H18) -> 0.072342544 | K18: =IF(F18="","n.a.",F18/H18) -> 1.2028959 | L18: =IF(D18="","n.a.",E18/D18) -> 1.0291365 | M18: =SUMIFS('IV history'!$N$7:$N$926,'IV history'!$A$7:$A$926,A18,'IV history'!$C$7:$C$926,"call") -> 3.579335e+08 | N18: =SUMIFS('IV history'!$N$7:$N$926,'IV history'!$A$7:$A$926,A18,'IV history'!$C$7:$C$926,"put") -> 1.2392328e+08 | O18: =IF(M18=0,"n.a.",N18/M18) -> 0.34621873 | P18: 0.43464811 | Q18: 0.43933024 | R18: =IF(OR(P18="",Q18=""),"n.a.",Q18-P18) -> 0.0046821267 | S18: =IF(OR(P18="",Q18="",F18=""),"n.a.",(P18+Q18)/2-F18) -> 0.008096604 | T18: 0.43581917 | U18: 0.41902083 | V18: 37
A19: 46273 | B19: 7015 | C19: 7000 | D19: 0.40410199 | E19: 0.45187481 | F19: 0.4279884 | G19: 0.25628549 | H19: 0.35879323 | I19: 0.3811233 | J19: =IF(F19="","n.a.",F19-H19) -> 0.069195178 | K19: =IF(F19="","n.a.",F19/H19) -> 1.1928553 | L19: =IF(D19="","n.a.",E19/D19) -> 1.1182197 | M19: =SUMIFS('IV history'!$N$7:$N$926,'IV history'!$A$7:$A$926,A19,'IV history'!$C$7:$C$926,"call") -> 2.0581124e+09 | N19: =SUMIFS('IV history'!$N$7:$N$926,'IV history'!$A$7:$A$926,A19,'IV history'!$C$7:$C$926,"put") -> 5.233237e+08 | O19: =IF(M19=0,"n.a.",N19/M19) -> 0.25427363 | P19: 0.41343696 | Q19: 0.45011605 | R19: =IF(OR(P19="",Q19=""),"n.a.",Q19-P19) -> 0.036679094 | S19: =IF(OR(P19="",Q19="",F19=""),"n.a.",(P19+Q19)/2-F19) -> 0.0037881001 | T19: 0.43681577 | U19: 0.41576458 | V19: 34
A20: 46274 | B20: 7085 | C20: 7000 | D20: 0.40296012 | E20: 0.44401835 | F20: 0.42348924 | G20: 0.26086488 | H20: 0.32323908 | I20: 0.38187929 | J20: =IF(F20="","n.a.",F20-H20) -> 0.10025016 | K20: =IF(F20="","n.a.",F20/H20) -> 1.3101425 | L20: =IF(D20="","n.a.",E20/D20) -> 1.1018915 | M20: =SUMIFS('IV history'!$N$7:$N$926,'IV history'!$A$7:$A$926,A20,'IV history'!$C$7:$C$926,"call") -> 1.9194413e+09 | N20: =SUMIFS('IV history'!$N$7:$N$926,'IV history'!$A$7:$A$926,A20,'IV history'!$C$7:$C$926,"put") -> 7.6649495e+08 | O20: =IF(M20=0,"n.a.",N20/M20) -> 0.39933233 | P20: 0.41373337 | Q20: 0.4368229 | R20: =IF(OR(P20="",Q20=""),"n.a.",Q20-P20) -> 0.023089535 | S20: =IF(OR(P20="",Q20="",F20=""),"n.a.",(P20+Q20)/2-F20) -> 0.0017888977 | T20: 0.43414016 | U20: 0.40905446 | V20: 33
A21: 46275 | B21: 7145 | C21: 7200 | D21: 0.38460585 | E21: 0.4446759 | F21: 0.41464087 | G21: 0.2245112 | H21: 0.32433464 | I21: 0.38244765 | J21: =IF(F21="","n.a.",F21-H21) -> 0.090306233 | K21: =IF(F21="","n.a.",F21/H21) -> 1.2784354 | L21: =IF(D21="","n.a.",E21/D21) -> 1.156186 | M21: =SUMIFS('IV history'!$N$7:$N$926,'IV history'!$A$7:$A$926,A21,'IV history'!$C$7:$C$926,"call") -> 2.9871927e+09 | N21: =SUMIFS('IV history'!$N$7:$N$926,'IV history'!$A$7:$A$926,A21,'IV history'!$C$7:$C$926,"put") -> 7.0780402e+08 | O21: =IF(M21=0,"n.a.",N21/M21) -> 0.23694622 | P21: 0.4076178 | Q21: 0.44284128 | R21: =IF(OR(P21="",Q21=""),"n.a.",Q21-P21) -> 0.035223483 | S21: =IF(OR(P21="",Q21="",F21=""),"n.a.",(P21+Q21)/2-F21) -> 0.010588666 | T21: 0.42154701 | U21: 0.40473147 | V21: 35
A22: 46276 | B22: 7000 | C22: 7000 | D22: 0.38691221 | E22: 0.44654618 | F22: 0.41672919 | G22: 0.2472373 | H22: 0.33069086 | I22: 0.3800381 | J22: =IF(F22="","n.a.",F22-H22) -> 0.086038332 | K22: =IF(F22="","n.a.",F22/H22) -> 1.2601775 | L22: =IF(D22="","n.a.",E22/D22) -> 1.1541279 | M22: =SUMIFS('IV history'!$N$7:$N$926,'IV history'!$A$7:$A$926,A22,'IV history'!$C$7:$C$926,"call") -> 2.1745863e+09 | N22: =SUMIFS('IV history'!$N$7:$N$926,'IV history'!$A$7:$A$926,A22,'IV history'!$C$7:$C$926,"put") -> 6.6986775e+08 | O22: =IF(M22=0,"n.a.",N22/M22) -> 0.30804376 | P22: 0.41012208 | Q22: 0.44259785 | R22: =IF(OR(P22="",Q22=""),"n.a.",Q22-P22) -> 0.032475769 | S22: =IF(OR(P22="",Q22="",F22=""),"n.a.",(P22+Q22)/2-F22) -> 0.0096307677 | T22: 0.4248847 | U22: 0.40539512 | V22: 34
... A25: 46281 | B25: 6760 | C25: 6800 | D25: 0.4043901 | E25: 0.462345 | F25: 0.43336755 | G25: 0.21176785 | H25: 0.29834284 | I25: 0.37763241 | J25: =IF(F25="","n.a.",F25-H25) -> 0.13502471 | K25: =IF(F25="","n.a.",F25/H25) -> 1.4525824 | L25: =IF(D25="","n.a.",E25/D25) -> 1.1433143 | M25: =SUMIFS('IV history'!$N$7:$N$926,'IV history'!$A$7:$A$926,A25,'IV history'!$C$7:$C$926,"call") -> 1.2163219e+09 | N25: =SUMIFS('IV history'!$N$7:$N$926,'IV history'!$A$7:$A$926,A25,'IV history'!$C$7:$C$926,"put") -> 4.9613355e+08 | O25: =IF(M25=0,"n.a.",N25/M25) -> 0.40789659 | P25: 0.4196761 | Q25: 0.45951091 | R25: =IF(OR(P25="",Q25=""),"n.a.",Q25-P25) -> 0.039834806 | S25: =IF(OR(P25="",Q25="",F25=""),"n.a.",(P25+Q25)/2-F25) -> 0.0062259547 | T25: 0.43922104 | U25: 0.42514605 | V25: 34

Sheet IV history
A2: Historical implied volatility estimates
A4: Model snapshot: 30% rate, zero dividends. Conditional on ticker strikes and PPI prices. See Model inputs.
A6: Date | B6: Ticker | C6: Type | D6: Strike | E6: PPI price | F6: GGAL spot | G6: Days to expiry | H6: Intrinsic | I6: Time value | J6: K / spot | K6: IV estimate | L6: BS delta | M6: BS vega / 1pp | N6: Raw volume | O6: Low | P6: High | Q6: Data status | R6: Source row
A7: 46281 | B7: GFGC6800OC | C7: call | D7: 6800 | E7: ='Option source'!B258 -> 376.43 | F7: 6760 | G7: 30 | H7: =MAX(IF(C7="call",F7-D7,D7-F7),0) -> 0 | I7: =E7-H7 -> 376.43 | J7: =D7/F7 -> 1.0059172 | K7: 0.4043901 | L7: 0.58697229 | M7: 7.5471612 | N7: ='Option source'!C258 -> 100339456 | O7: ='Option source'!G258 -> 330 | P7: ='Option source'!F258 -> 429.88 | Q7: Screen passed; indicative | R7: 253
A8: 46281 | B8: GFGV6800OC | C8: put | D8: 6800 | E8: ='Option source'!B752 -> 312.15 | F8: 6760 | G8: 30 | H8: =MAX(IF(C8="call",F8-D8,D8-F8),0) -> 40 | I8: =E8-H8 -> 272.15 | J8: =D8/F8 -> 1.0059172 | K8: 0.462345 | L8: -0.41769652 | M8: 7.5665041 | N8: ='Option source'!C752 -> 81244632 | O8: ='Option source'!G752 -> 285 | P8: ='Option source'!F752 -> 345 | Q8: Screen passed; indicative | R8: 747
A9: 46281 | B9: GFGC6600OC | C9: call | D9: 6600 | E9: ='Option source'!B239 -> 478.22 | F9: 6760 | G9: 30 | H9: =MAX(IF(C9="call",F9-D9,D9-F9),0) -> 160 | I9: =E9-H9 -> 318.22 | J9: =D9/F9 -> 0.97633136 | K9: 0.38456052 | L9: 0.69006648 | M9: 6.8366115 | N9: ='Option source'!C239 -> 55284376 | O9: ='Option source'!G239 -> 435 | P9: ='Option source'!F239 -> 540 | Q9: Screen passed; indicative | R9: 234
A10: 46281 | B10: GFGV6600OC | C10: put | D10: 6600 | E10: ='Option source'!B733 -> 222.45 | F10: 6760 | G10: 30 | H10: =MAX(IF(C10="call",F10-D10,D10-F10),0) -> 0 | I10: =E10-H10 -> 222.45 | J10: =D10/F10 -> 0.97633136 | K10: 0.46193164 | L10: -0.33240609 | M10: 7.0389159 | N10: ='Option source'!C733 -> 124328488 | O10: ='Option source'!G733 -> 198.18 | P10: ='Option source'!F733 -> 249 | Q10: Screen passed; indicative | R10: 728
A11: 46281 | B11: GFGC7000OC | C11: call | D11: 7000 | E11: ='Option source'!B277 -> 289.65 | F11: 6760 | G11: 30 | H11: =MAX(IF(C11="call",F11-D11,D11-F11),0) -> 0 | I11: =E11-H11 -> 289.65 | J11: =D11/F11 -> 1.035503 | K11: 0.41615491 | L11: 0.48959347 | M11: 7.7289975 | N11: ='Option source'!C277 -> 223562320 | O11: ='Option source'!G277 -> 237 | P11: ='Option source'!F277 -> 329.06 | Q11: Screen passed; indicative | R11: 272
A12: 46281 | B12: GFGV7000OC | C12: put | D12: 7000 | E12: ='Option source'!B771 -> 427.03 | F12: 6760 | G12: 30 | H12: =MAX(IF(C12="call",F12-D12,D12-F12),0) -> 240 | I12: =E12-H12 -> 187.03 | J12: =D12/F12 -> 1.035503 | K12: 0.47075019 | L12: -0.50331849 | M12: 7.7313606 | N12: ='Option source'!C771 -> 45682320 | O12: ='Option source'!G771 -> 385 | P12: ='Option source'!F771 -> 465 | Q12: Screen passed; indicative | R12: 766
A13: 46281 | B13: GFGC6400OC | C13: call | D13: 6400 | E13: ='Option source'!B220 -> 616.1 | F13: 6760 | G13: 30 | H13: =MAX(IF(C13="call",F13-D13,D13-F13),0) -> 360 | I13: =E13-H13 -> 256.1 | J13: =D13/F13 -> 0.94674556 | K13: 0.38698396 | L13: 0.77964208 | M13: 5.7437399 | N13: ='Option source'!C220 -> 27128652 | O13: ='Option source'!G220 -> 570 | P13: ='Option source'!F220 -> 670 | Q13: Screen passed; indicative | R13: 215
A14: 46281 | B14: GFGV6400OC | C14: put | D14: 6400 | E14: ='Option source'!B714 -> 150.25 | F14: 6760 | G14: 30 | H14: =MAX(IF(C14="call",F14-D14,D14-F14),0) -> 0 | I14: =E14-H14 -> 150.25 | J14: =D14/F14 -> 0.94674556 | K14: 0.4595281 | L14: -0.25193011 | M14: 6.1837276 | N14: ='Option source'!C714 -> 109657352 | O14: ='Option source'!G714 -> 132.99 | P14: ='Option source'!F714 -> 171 | Q14: Screen passed; indicative | R14: 709
A15: 46281 | B15: GFGC7200OC | C15: call | D15: 7200 | E15: ='Option source'!B296 -> 213.18 | F15: 6760 | G15: 30 | H15: =MAX(IF(C15="call",F15-D15,D15-F15),0) -> 0 | I15: =E15-H15 -> 213.18 | J15: =D15/F15 -> 1.0650888 | K15: 0.4172588 | L15: 0.39697005 | M15: 7.4723337 | N15: ='Option source'!C296 -> 147861040 | O15: ='Option source'!G296 -> 181 | P15: ='Option source'!F296 -> 245 | Q15: Screen passed; indicative | R15: 291
A16: 46281 | B16: GFGV7200OC | C16: put | D16: 7200 | E16: ='Option source'!B790 -> 550.35 | F16: 6760 | G16: 30 | H16: =MAX(IF(C16="call",F16-D16,D16-F16),0) -> 440 | I16: =E16-H16 -> 110.35 | J16: =D16/F16 -> 1.0650888 | K16: 0.46356595 | L16: -0.58803493 | M16: 7.5426072 | N16: ='Option source'!C790 -> 10836713 | O16: ='Option source'!G790 -> 521 | P16: ='Option source'!F790 -> 590 | Q16: Screen passed; indicative | R16: 785
A17: 46281 | B17: GFGC6200OC | C17: call | D17: 6200 | E17: ='Option source'!B201 -> 704.74 | F17: 6760 | G17: 30 | H17: =MAX(IF(C17="call",F17-D17,D17-F17),0) -> 560 | I17: =E17-H17 -> 144.74 | J17: =D17/F17 -> 0.91715976 | N17: ='Option source'!C201 -> 13875889 | O17: ='Option source'!G201 -> 700 | P17: ='Option source'!F201 -> 810 | Q17: No stable model IV | R17: 196
A18: 46281 | B18: GFGV6200OC | C18: put | D18: 6200 | E18: ='Option source'!B695 -> 97.41 | F18: 6760 | G18: 30 | H18: =MAX(IF(C18="call",F18-D18,D18-F18),0) -> 0 | I18: =E18-H18 -> 97.41 | J18: =D18/F18 -> 0.91715976 | K18: 0.45889878 | L18: -0.18128332 | M18: 5.1081012 | N18: ='Option source'!C695 -> 54669212 | O18: ='Option source'!G695 -> 83.05 | P18: ='Option source'!F695 -> 117.6 | Q18: Screen passed; indicative | R18: 690
A19: 46281 | B19: GFGC7400OC | C19: call | D19: 7400 | E19: ='Option source'!B315 -> 157.14 | F19: 6760 | G19: 30 | H19: =MAX(IF(C19="call",F19-D19,D19-F19),0) -> 0 | I19: =E19-H19 -> 157.14 | J19: =D19/F19 -> 1.0946746 | K19: 0.42384091 | L19: 0.31534577 | M19: 6.887839 | N19: ='Option source'!C315 -> 192882096 | O19: ='Option source'!G315 -> 111 | P19: ='Option source'!F315 -> 177.99 | Q19: Screen passed; indicative | R19: 310
A20: 46281 | B20: GFGV7400OC | C20: put | D20: 7400 | E20: ='Option source'!B809 -> 677.83 | F20: 6760 | G20: 30 | H20: =MAX(IF(C20="call",F20-D20,D20-F20),0) -> 640 | I20: =E20-H20 -> 37.83 | J20: =D20/F20 -> 1.0946746 | K20: 0.42688101 | L20: -0.68312718 | M20: 6.9020032 | N20: ='Option source'!C809 -> 6190239 | O20: ='Option source'!G809 -> 630.55 | P20: ='Option source'!F809 -> 715.55 | Q20: Screen passed; indicative | R20: 804
A21: 46281 | B21: GFGC6000OC | C21: call | D21: 6000 | E21: ='Option source'!B182 -> 916.41 | F21: 6760 | G21: 30 | H21: =MAX(IF(C21="call",F21-D21,D21-F21),0) -> 760 | I21: =E21-H21 -> 156.41 | J21: =D21/F21 -> 0.88757396 | K21: 0.2984427 | L21: 0.95772446 | M21: 1.746708 | N21: ='Option source'!C182 -> 11611929 | O21: ='Option source'!G182 -> 856.28 | P21: ='Option source'!F182 -> 946.54 | Q21: Screen passed; indicative | R21: 177
A22: 46281 | B22: GFGV6000OC | C22: put | D22: 6000 | E22: ='Option source'!B676 -> 56.82 | F22: 6760 | G22: 30 | H22: =MAX(IF(C22="call",F22-D22,D22-F22),0) -> 0 | I22: =E22-H22 -> 56.82 | J22: =D22/F22 -> 0.88757396 | K22: 0.45172074 | L22: -0.11978268 | M22: 3.871897 | N22: ='Option source'!C676 -> 31602294 | O22: ='Option source'!G676 -> 48.93 | P22: ='Option source'!F676 -> 69.71 | Q22: Screen passed; indicative | R22: 671
A23: 46281 | B23: GFGC7600OC | C23: call | D23: 7600 | E23: ='Option source'!B334 -> 107.66 | F23: 6760 | G23: 30 | H23: =MAX(IF(C23="call",F23-D23,D23-F23),0) -> 0 | I23: =E23-H23 -> 107.66 | J23: =D23/F23 -> 1.1242604 | K23: 0.41897014 | L23: 0.23892342 | M23: 6.0100484 | N23: ='Option source'!C334 -> 235477376 | O23: ='Option source'!G334 -> 95 | P23: ='Option source'!F334 -> 127 | Q23: Screen passed; indicative | R23: 329
A24: 46281 | B24: GFGV7600OC | C24: put | D24: 7600 | E24: ='Option source'!B828 -> 857 | F24: 6760 | G24: 30 | H24: =MAX(IF(C24="call",F24-D24,D24-F24),0) -> 840 | I24: =E24-H24 -> 17 | J24: =D24/F24 -> 1.1242604 | K24: 0.4489615 | L24: -0.74345861 | M24: 6.24282 | N24: ='Option source'!C828 -> 4665704 | O24: ='Option source'!G828 -> 753.12 | P24: ='Option source'!F828 -> 916 | Q24: Screen passed; indicative | R24: 823
A25: 46281 | B25: GFGC5800OC | C25: call | D25: 5800 | E25: ='Option source'!B163 -> 1049.9 | F25: 6760 | G25: 30 | H25: =MAX(IF(C25="call",F25-D25,D25-F25),0) -> 960 | I25: =E25-H25 -> 89.9 | J25: =D25/F25 -> 0.85798817 | N25: ='Option source'!C163 -> 1980739.2 | O25: ='Option source'!G163 -> 1059.3 | P25: ='Option source'!F163 -> 1142.92 | Q25: Price outside daily range | R25: 158
A26: 46281 | B26: GFGV5800OC | C26: put | D26: 5800 | E26: ='Option source'!B657 -> 31.98 | F26: 6760 | G26: 30 | H26: =MAX(IF(C26="call",F26-D26,D26-F26),0) -> 0 | I26: =E26-H26 -> 31.98 | J26: =D26/F26 -> 0.85798817 | K26: 0.45084665 | L26: -0.07487854 | M26: 2.7399995 | N26: ='Option source'!C657 -> 14883324 | O26: ='Option source'!G657 -> 26.55 | P26: ='Option source'!F657 -> 37.89 | Q26: Screen passed; indicative | R26: 652
A27: 46281 | B27: GFGC7800OC | C27: call | D27: 7800 | E27: ='Option source'!B353 -> 75.86 | F27: 6760 | G27: 30 | H27: =MAX(IF(C27="call",F27-D27,D27-F27),0) -> 0 | I27: =E27-H27 -> 75.86 | J27: =D27/F27 -> 1.1538462 | K27: 0.42340313 | L27: 0.18007865 | M27: 5.0867907 | N27: ='Option source'!C353 -> 97534584 | O27: ='Option source'!G353 -> 67.01 | P27: ='Option source'!F353 -> 89.99 | Q27: Screen passed; indicative | R27: 348
A28: 46281 | B28: GFGV7800OC | C28: put | D28: 7800 | E28: ='Option source'!B847 -> 1000 | F28: 6760 | G28: 30 | H28: =MAX(IF(C28="call",F28-D28,D28-F28),0) -> 1040 | I28: =E28-H28 -> -40 | J28: =D28/F28 -> 1.1538462 | N28: ='Option source'!C847 -> 302000 | O28: ='Option source'!G847 -> 1020 | P28: ='Option source'!F847 -> 1020 | Q28: Price outside daily range; Below intrinsic value | R28: 842
A29: 46281 | B29: GFGC5600OC | C29: call | D29: 5600 | E29: ='Option source'!B153 -> 1233.13 | F29: 6760 | G29: 30 | H29: =MAX(IF(C29="call",F29-D29,D29-F29),0) -> 1160 | I29: =E29-H29 -> 73.13 | J29: =D29/F29 -> 0.82840237 | N29: ='Option source'!C153 -> 1870673.8 | O29: ='Option source'!G153 -> 1227.44 | P29: ='Option source'!F153 -> 1335.39 | Q29: No stable model IV | R29: 148
A30: 46281 | B30: GFGV5600OC | C30: put | D30: 5600 | E30: ='Option source'!B638 -> 17.15 | F30: 6760 | G30: 30 | H30: =MAX(IF(C30="call",F30-D30,D30-F30),0) -> 0 | I30: =E30-H30 -> 17.15 | J30: =D30/F30 -> 0.82840237 | K30: 0.45291432 | L30: -0.044129109 | M30: 1.808305 | N30: ='Option source'!C638 -> 7799133.5 | O30: ='Option source'!G638 -> 14.36 | P30: ='Option source'!F638 -> 22.99 | Q30: Screen passed; indicative | R30: 633
A31: 46281 | B31: GFGC8000OC | C31: call | D31: 8000 | E31: ='Option source'!B372 -> 54.71 | F31: 6760 | G31: 30 | H31: =MAX(IF(C31="call",F31-D31,D31-F31),0) -> 0 | I31: =E31-H31 -> 54.71 | J31: =D31/F31 -> 1.183432 | K31: 0.43226054 | L31: 0.13608028 | M31: 4.2308673 | N31: ='Option source'!C372 -> 66091964 | O31: ='Option source'!G372 -> 46.6 | P31: ='Option source'!F372 -> 62.99 | Q31: Screen passed; indicative | R31: 367
A32: 46281 | B32: GFGV8000OC | C32: put | D32: 8000 | E32: ='Option source'!B866 -> 1230 | F32: 6760 | G32: 30 | H32: =MAX(IF(C32="call",F32-D32,D32-F32),0) -> 1240 | I32: =E32-H32 -> -10 | J32: =D32/F32 -> 1.183432 | N32: ='Option source'!C866 -> 0 | O32: ='Option source'!G866 -> 1109 | P32: ='Option source'!F866 -> 1250 | Q32: Zero reported volume; Below intrinsic value | R32: 861
A33: 46281 | B33: GFGC5400OC | C33: call | D33: 5400 | E33: ='Option source'!B135 -> 1470 | F33: 6760 | G33: 30 | H33: =MAX(IF(C33="call",F33-D33,D33-F33),0) -> 1360 | I33: =E33-H33 -> 110 | J33: =D33/F33 -> 0.79881657 | N33: ='Option source'!C135 -> 0 | O33: ='Option source'!G135 -> 1424.19 | P33: ='Option source'!F135 -> 1532.25 | Q33: Zero reported volume | R33: 130
A34: 46281 | B34: GFGV5400OC | C34: put | D34: 5400 | E34: ='Option source'!B619 -> 9.02 | F34: 6760 | G34: 30 | H34: =MAX(IF(C34="call",F34-D34,D34-F34),0) -> 0 | I34: =E34-H34 -> 9.02 | J34: =D34/F34 -> 0.79881657 | K34: 0.45968663 | L34: -0.025148639 | M34: 1.1383264 | N34: ='Option source'!C619 -> 1795599.1 | O34: ='Option source'!G619 -> 7.3 | P34: ='Option source'!F619 -> 12.63 | Q34: Screen passed; indicative | R34: 614
A35: 46281 | B35: GFGC8300OC | C35: call | D35: 8300 | E35: ='Option source'!B391 -> 32.2 | F35: 6760 | G35: 30 | H35: =MAX(IF(C35="call",F35-D35,D35-F35),0) -> 0 | I35: =E35-H35 -> 32.2 | J35: =D35/F35 -> 1.2278107 | K35: 0.44108035 | L35: 0.086163364 | M35: 3.046602 | N35: ='Option source'!C391 -> 26771796 | O35: ='Option source'!G391 -> 27 | P35: ='Option source'!F391 -> 38 | Q35: Screen passed; indicative | R35: 386
A36: 46281 | B36: GFGV8300OC | C36: put | D36: 8300 | E36: ='Option source'!B885 -> 1520 | F36: 6760 | G36: 30 | H36: =MAX(IF(C36="call",F36-D36,D36-F36),0) -> 1540 | I36: =E36-H36 -> -20 | J36: =D36/F36 -> 1.2278107 | N36: ='Option source'!C885 -> 0 | O36: ='Option source'!G885 -> 1520 | P36: ='Option source'!F885 -> 1520 | Q36: Zero reported volume; Below intrinsic value | R36: 880
A37: 46281 | B37: GFGC5200OC | C37: call | D37: 5200 | E37: ='Option source'!B116 -> 1678.07 | F37: 6760 | G37: 30 | H37: =MAX(IF(C37="call",F37-D37,D37-F37),0) -> 1560 | I37: =E37-H37 -> 118.07 | J37: =D37/F37 -> 0.76923077 | N37: ='Option source'!C116 -> 0 | O37: ='Option source'!G116 -> 1653.01 | P37: ='Option source'!F116 -> 1700 | Q37: Zero reported volume | R37: 111
A38: 46281 | B38: GFGV5200OC | C38: put | D38: 5200 | E38: ='Option source'!B600 -> 6.01 | F38: 6760 | G38: 30 | H38: =MAX(IF(C38="call",F38-D38,D38-F38),0) -> 0 | I38: =E38-H38 -> 6.01 | J38: =D38/F38 -> 0.76923077 | K38: 0.48616181 | L38: -0.016627535 | M38: 0.80173253 | N38: ='Option source'!C600 -> 533764.69 | O38: ='Option source'!G600 -> 3.59 | P38: ='Option source'!F600 -> 7.7 | Q38: Screen passed; indicative | R38: 595
A39: 46281 | B39: GFGC5000OC | C39: call | D39: 5000 | E39: ='Option source'!B97 -> 1808.85 | F39: 6760 | G39: 30 | H39: =MAX(IF(C39="call",F39-D39,D39-F39),0) -> 1760 | I39: =E39-H39 -> 48.85 | J39: =D39/F39 -> 0.73964497 | N39: ='Option source'!C97 -> 361770.59 | O39: ='Option source'!G97 -> 0 | P39: ='Option source'!F97 -> 0 | Q39: Price outside daily range | R39: 92
A40: 46281 | B40: GFGV5000OC | C40: put | D40: 5000 | E40: ='Option source'!B581 -> 3.18 | F40: 6760 | G40: 30 | H40: =MAX(IF(C40="call",F40-D40,D40-F40),0) -> 0 | I40: =E40-H40 -> 3.18 | J40: =D40/F40 -> 0.73964497 | K40: 0.49860677 | L40: -0.0092925735 | M40: 0.48444657 | N40: ='Option source'!C581 -> 745490.69 | O40: ='Option source'!G581 -> 2 | P40: ='Option source'!F581 -> 3.99 | Q40: Screen passed; indicative | R40: 576
A41: 46281 | B41: GFGC8600OC | C41: call | D41: 8600 | E41: ='Option source'!B410 -> 17.94 | F41: 6760 | G41: 30 | H41: =MAX(IF(C41="call",F41-D41,D41-F41),0) -> 0 | I41: =E41-H41 -> 17.94 | J41: =D41/F41 -> 1.2721893 | K41: 0.44561207 | L41: 0.051812702 | M41: 2.0562806 | N41: ='Option source'!C410 -> 7674966 | O41: ='Option source'!G410 -> 16 | P41: ='Option source'!F410 -> 24 | Q41: Screen passed; indicative | R41: 405
A42: 46281 | B42: GFGV8600OC | C42: put | D42: 8600 | E42: ='Option source'!B904 -> 1648.65 | F42: 6760 | G42: 30 | H42: =MAX(IF(C42="call",F42-D42,D42-F42),0) -> 1840 | I42: =E42-H42 -> -191.35 | J42: =D42/F42 -> 1.2721893 | N42: ='Option source'!C904 -> 0 | O42: ='Option source'!G904 -> 1648.65 | P42: ='Option source'!F904 -> 1648.65 | Q42: Zero reported volume; Below intrinsic value | R42: 899
A43: 46281 | B43: GFGC4800OC | C43: call | D43: 4800 | E43: ='Option source'!B80 -> 2084.21 | F43: 6760 | G43: 30 | H43: =MAX(IF(C43="call",F43-D43,D43-F43),0) -> 1960 | I43: =E43-H43 -> 124.21 | J43: =D43/F43 -> 0.71005917 | N43: ='Option source'!C80 -> 0 | O43: ='Option source'!G80 -> 2009.47 | P43: ='Option source'!F80 -> 2064.28 | Q43: Zero reported volume; Price outside daily range | R43: 75
...

Sheet Strategies
A2: Butterflies and 1x2 ratio spreads
A4: Indicative PPI prices only. Expiration P&L excludes costs and early assignment. 1x2 calls have unlimited upside loss.
A6: Date | B6: Strategy | C6: Type | D6: Long strike 1 | E6: Short strike 2 (x2) | F6: Long strike 3 | G6: Premium 1 | H6: Premium 2 | I6: Premium 3 | J6: Net debit / share | K6: Strike width | L6: Peak P&L / share | M6: Max loss / share | N6: Lower breakeven | O6: Upper breakeven | P6: Peak / debit | Q6: Net debit / set | R6: Data status | S6: Long leg source | T6: Short leg source
A7: 46281 | B7: Butterfly | C7: call | D7: 6600 | E7: 6800 | F7: 7000 | G7: ='Option source'!B239 -> 478.22 | H7: ='Option source'!B258 -> 376.43 | I7: ='Option source'!B277 -> 289.65 | J7: =G7-2*H7+IF(B7="Butterfly",I7,0) -> 15.01 | K7: =ABS(E7-D7) -> 200 | L7: =K7-J7 -> 184.99 | M7: =IF(B7="Butterfly",MAX(J7,0),IF(C7="call","Unlimited",MAX(2*E7-D7+J7,J7,0))) -> 15.01 | N7: =IF(B7="Butterfly",IF(AND(J7>0,J7<K7),D7+J7,"n.a."),IF(C7="call",IF(AND(J7>0,J7<K7),D7+J7,"n.a."),IF(AND(K7>J7,2*E7-D7+J7>=0),2*E7-D7+J7,"n.a."))) -> 6615.01 | O7: =IF(B7="Butterfly",IF(AND(J7>0,J7<K7),F7-J7,"n.a."),IF(C7="call",IF(K7>J7,2*E7-D7-J7,"n.a."),IF(AND(J7>0,J7<K7),D7-J7,"n.a."))) -> 6984.99 | P7: =IF(AND(B7="Butterfly",J7>0,J7<K7),L7/J7,"n.a.") -> 12.32445 | Q7: =J7*'Model inputs'!$B$8 -> 1501 | R7: Indicative only | S7: 234 | T7: 253
A8: 46281 | B8: Butterfly | C8: put | D8: 6600 | E8: 6800 | F8: 7000 | G8: ='Option source'!B733 -> 222.45 | H8: ='Option source'!B752 -> 312.15 | I8: ='Option source'!B771 -> 427.03 | J8: =G8-2*H8+IF(B8="Butterfly",I8,0) -> 25.18 | K8: =ABS(E8-D8) -> 200 | L8: =K8-J8 -> 174.82 | M8: =IF(B8="Butterfly",MAX(J8,0),IF(C8="call","Unlimited",MAX(2*E8-D8+J8,J8,0))) -> 25.18 | N8: =IF(B8="Butterfly",IF(AND(J8>0,J8<K8),D8+J8,"n.a."),IF(C8="call",IF(AND(J8>0,J8<K8),D8+J8,"n.a."),IF(AND(K8>J8,2*E8-D8+J8>=0),2*E8-D8+J8,"n.a."))) -> 6625.18 | O8: =IF(B8="Butterfly",IF(AND(J8>0,J8<K8),F8-J8,"n.a."),IF(C8="call",IF(K8>J8,2*E8-D8-J8,"n.a."),IF(AND(J8>0,J8<K8),D8-J8,"n.a."))) -> 6974.82 | P8: =IF(AND(B8="Butterfly",J8>0,J8<K8),L8/J8,"n.a.") -> 6.9428118 | Q8: =J8*'Model inputs'!$B$8 -> 2518 | R8: Indicative only | S8: 728 | T8: 747
A9: 46281 | B9: Butterfly | C9: call | D9: 6400 | E9: 6600 | F9: 6800 | G9: ='Option source'!B220 -> 616.1 | H9: ='Option source'!B239 -> 478.22 | I9: ='Option source'!B258 -> 376.43 | J9: =G9-2*H9+IF(B9="Butterfly",I9,0) -> 36.09 | K9: =ABS(E9-D9) -> 200 | L9: =K9-J9 -> 163.91 | M9: =IF(B9="Butterfly",MAX(J9,0),IF(C9="call","Unlimited",MAX(2*E9-D9+J9,J9,0))) -> 36.09 | N9: =IF(B9="Butterfly",IF(AND(J9>0,J9<K9),D9+J9,"n.a."),IF(C9="call",IF(AND(J9>0,J9<K9),D9+J9,"n.a."),IF(AND(K9>J9,2*E9-D9+J9>=0),2*E9-D9+J9,"n.a."))) -> 6436.09 | O9: =IF(B9="Butterfly",IF(AND(J9>0,J9<K9),F9-J9,"n.a."),IF(C9="call",IF(K9>J9,2*E9-D9-J9,"n.a."),IF(AND(J9>0,J9<K9),D9-J9,"n.a."))) -> 6763.91 | P9: =IF(AND(B9="Butterfly",J9>0,J9<K9),L9/J9,"n.a.") -> 4.5417013 | Q9: =J9*'Model inputs'!$B$8 -> 3609 | R9: Indicative only | S9: 215 | T9: 234
A10: 46281 | B10: Butterfly | C10: put | D10: 6400 | E10: 6600 | F10: 6800 | G10: ='Option source'!B714 -> 150.25 | H10: ='Option source'!B733 -> 222.45 | I10: ='Option source'!B752 -> 312.15 | J10: =G10-2*H10+IF(B10="Butterfly",I10,0) -> 17.5 | K10: =ABS(E10-D10) -> 200 | L10: =K10-J10 -> 182.5 | M10: =IF(B10="Butterfly",MAX(J10,0),IF(C10="call","Unlimited",MAX(2*E10-D10+J10,J10,0))) -> 17.5 | N10: =IF(B10="Butterfly",IF(AND(J10>0,J10<K10),D10+J10,"n.a."),IF(C10="call",IF(AND(J10>0,J10<K10),D10+J10,"n.a."),IF(AND(K10>J10,2*E10-D10+J10>=0),2*E10-D10+J10,"n.a."))) -> 6417.5 | O10: =IF(B10="Butterfly",IF(AND(J10>0,J10<K10),F10-J10,"n.a."),IF(C10="call",IF(K10>J10,2*E10-D10-J10,"n.a."),IF(AND(J10>0,J10<K10),D10-J10,"n.a."))) -> 6782.5 | P10: =IF(AND(B10="Butterfly",J10>0,J10<K10),L10/J10,"n.a.") -> 10.428571 | Q10: =J10*'Model inputs'!$B$8 -> 1750 | R10: Indicative only | S10: 709 | T10: 728
A11: 46281 | B11: Butterfly | C11: call | D11: 6800 | E11: 7000 | F11: 7200 | G11: ='Option source'!B258 -> 376.43 | H11: ='Option source'!B277 -> 289.65 | I11: ='Option source'!B296 -> 213.18 | J11: =G11-2*H11+IF(B11="Butterfly",I11,0) -> 10.31 | K11: =ABS(E11-D11) -> 200 | L11: =K11-J11 -> 189.69 | M11: =IF(B11="Butterfly",MAX(J11,0),IF(C11="call","Unlimited",MAX(2*E11-D11+J11,J11,0))) -> 10.31 | N11: =IF(B11="Butterfly",IF(AND(J11>0,J11<K11),D11+J11,"n.a."),IF(C11="call",IF(AND(J11>0,J11<K11),D11+J11,"n.a."),IF(AND(K11>J11,2*E11-D11+J11>=0),2*E11-D11+J11,"n.a."))) -> 6810.31 | O11: =IF(B11="Butterfly",IF(AND(J11>0,J11<K11),F11-J11,"n.a."),IF(C11="call",IF(K11>J11,2*E11-D11-J11,"n.a."),IF(AND(J11>0,J11<K11),D11-J11,"n.a."))) -> 7189.69 | P11: =IF(AND(B11="Butterfly",J11>0,J11<K11),L11/J11,"n.a.") -> 18.398642 | Q11: =J11*'Model inputs'!$B$8 -> 1031 | R11: Indicative only | S11: 253 | T11: 272
A12: 46281 | B12: Butterfly | C12: put | D12: 6800 | E12: 7000 | F12: 7200 | G12: ='Option source'!B752 -> 312.15 | H12: ='Option source'!B771 -> 427.03 | I12: ='Option source'!B790 -> 550.35 | J12: =G12-2*H12+IF(B12="Butterfly",I12,0) -> 8.44 | K12: =ABS(E12-D12) -> 200 | L12: =K12-J12 -> 191.56 | M12: =IF(B12="Butterfly",MAX(J12,0),IF(C12="call","Unlimited",MAX(2*E12-D12+J12,J12,0))) -> 8.44 | N12: =IF(B12="Butterfly",IF(AND(J12>0,J12<K12),D12+J12,"n.a."),IF(C12="call",IF(AND(J12>0,J12<K12),D12+J12,"n.a."),IF(AND(K12>J12,2*E12-D12+J12>=0),2*E12-D12+J12,"n.a."))) -> 6808.44 | O12: =IF(B12="Butterfly",IF(AND(J12>0,J12<K12),F12-J12,"n.a."),IF(C12="call",IF(K12>J12,2*E12-D12-J12,"n.a."),IF(AND(J12>0,J12<K12),D12-J12,"n.a."))) -> 7191.56 | P12: =IF(AND(B12="Butterfly",J12>0,J12<K12),L12/J12,"n.a.") -> 22.696682 | Q12: =J12*'Model inputs'!$B$8 -> 844 | R12: Indicative only | S12: 747 | T12: 766
A13: 46281 | B13: Butterfly | C13: put | D13: 6200 | E13: 6400 | F13: 6600 | G13: ='Option source'!B695 -> 97.41 | H13: ='Option source'!B714 -> 150.25 | I13: ='Option source'!B733 -> 222.45 | J13: =G13-2*H13+IF(B13="Butterfly",I13,0) -> 19.36 | K13: =ABS(E13-D13) -> 200 | L13: =K13-J13 -> 180.64 | M13: =IF(B13="Butterfly",MAX(J13,0),IF(C13="call","Unlimited",MAX(2*E13-D13+J13,J13,0))) -> 19.36 | N13: =IF(B13="Butterfly",IF(AND(J13>0,J13<K13),D13+J13,"n.a."),IF(C13="call",IF(AND(J13>0,J13<K13),D13+J13,"n.a."),IF(AND(K13>J13,2*E13-D13+J13>=0),2*E13-D13+J13,"n.a."))) -> 6219.36 | O13: =IF(B13="Butterfly",IF(AND(J13>0,J13<K13),F13-J13,"n.a."),IF(C13="call",IF(K13>J13,2*E13-D13-J13,"n.a."),IF(AND(J13>0,J13<K13),D13-J13,"n.a."))) -> 6580.64 | P13: =IF(AND(B13="Butterfly",J13>0,J13<K13),L13/J13,"n.a.") -> 9.3305785 | Q13: =J13*'Model inputs'!$B$8 -> 1936 | R13: Indicative only | S13: 690 | T13: 709
A14: 46281 | B14: Butterfly | C14: call | D14: 7000 | E14: 7200 | F14: 7400 | G14: ='Option source'!B277 -> 289.65 | H14: ='Option source'!B296 -> 213.18 | I14: ='Option source'!B315 -> 157.14 | J14: =G14-2*H14+IF(B14="Butterfly",I14,0) -> 20.43 | K14: =ABS(E14-D14) -> 200 | L14: =K14-J14 -> 179.57 | M14: =IF(B14="Butterfly",MAX(J14,0),IF(C14="call","Unlimited",MAX(2*E14-D14+J14,J14,0))) -> 20.43 | N14: =IF(B14="Butterfly",IF(AND(J14>0,J14<K14),D14+J14,"n.a."),IF(C14="call",IF(AND(J14>0,J14<K14),D14+J14,"n.a."),IF(AND(K14>J14,2*E14-D14+J14>=0),2*E14-D14+J14,"n.a."))) -> 7020.43 | O14: =IF(B14="Butterfly",IF(AND(J14>0,J14<K14),F14-J14,"n.a."),IF(C14="call",IF(K14>J14,2*E14-D14-J14,"n.a."),IF(AND(J14>0,J14<K14),D14-J14,"n.a."))) -> 7379.57 | P14: =IF(AND(B14="Butterfly",J14>0,J14<K14),L14/J14,"n.a.") -> 8.7895252 | Q14: =J14*'Model inputs'!$B$8 -> 2043 | R14: Indicative only | S14: 272 | T14: 291
A15: 46281 | B15: Butterfly | C15: put | D15: 7000 | E15: 7200 | F15: 7400 | G15: ='Option source'!B771 -> 427.03 | H15: ='Option source'!B790 -> 550.35 | I15: ='Option source'!B809 -> 677.83 | J15: =G15-2*H15+IF(B15="Butterfly",I15,0) -> 4.16 | K15: =ABS(E15-D15) -> 200 | L15: =K15-J15 -> 195.84 | M15: =IF(B15="Butterfly",MAX(J15,0),IF(C15="call","Unlimited",MAX(2*E15-D15+J15,J15,0))) -> 4.16 | N15: =IF(B15="Butterfly",IF(AND(J15>0,J15<K15),D15+J15,"n.a."),IF(C15="call",IF(AND(J15>0,J15<K15),D15+J15,"n.a."),IF(AND(K15>J15,2*E15-D15+J15>=0),2*E15-D15+J15,"n.a."))) -> 7004.16 | O15: =IF(B15="Butterfly",IF(AND(J15>0,J15<K15),F15-J15,"n.a."),IF(C15="call",IF(K15>J15,2*E15-D15-J15,"n.a."),IF(AND(J15>0,J15<K15),D15-J15,"n.a."))) -> 7395.84 | P15: =IF(AND(B15="Butterfly",J15>0,J15<K15),L15/J15,"n.a.") -> 47.076923 | Q15: =J15*'Model inputs'!$B$8 -> 416 | R15: Indicative only | S15: 766 | T15: 785
A16: 46281 | B16: Butterfly | C16: put | D16: 6000 | E16: 6200 | F16: 6400 | G16: ='Option source'!B676 -> 56.82 | H16: ='Option source'!B695 -> 97.41 | I16: ='Option source'!B714 -> 150.25 | J16: =G16-2*H16+IF(B16="Butterfly",I16,0) -> 12.25 | K16: =ABS(E16-D16) -> 200 | L16: =K16-J16 -> 187.75 | M16: =IF(B16="Butterfly",MAX(J16,0),IF(C16="call","Unlimited",MAX(2*E16-D16+J16,J16,0))) -> 12.25 | N16: =IF(B16="Butterfly",IF(AND(J16>0,J16<K16),D16+J16,"n.a."),IF(C16="call",IF(AND(J16>0,J16<K16),D16+J16,"n.a."),IF(AND(K16>J16,2*E16-D16+J16>=0),2*E16-D16+J16,"n.a."))) -> 6012.25 | O16: =IF(B16="Butterfly",IF(AND(J16>0,J16<K16),F16-J16,"n.a."),IF(C16="call",IF(K16>J16,2*E16-D16-J16,"n.a."),IF(AND(J16>0,J16<K16),D16-J16,"n.a."))) -> 6387.75 | P16: =IF(AND(B16="Butterfly",J16>0,J16<K16),L16/J16,"n.a.") -> 15.326531 | Q16: =J16*'Model inputs'!$B$8 -> 1225 | R16: Indicative only | S16: 671 | T16: 690
A17: 46281 | B17: Butterfly | C17: call | D17: 7200 | E17: 7400 | F17: 7600 | G17: ='Option source'!B296 -> 213.18 | H17: ='Option source'!B315 -> 157.14 | I17: ='Option source'!B334 -> 107.66 | J17: =G17-2*H17+IF(B17="Butterfly",I17,0) -> 6.56 | K17: =ABS(E17-D17) -> 200 | L17: =K17-J17 -> 193.44 | M17: =IF(B17="Butterfly",MAX(J17,0),IF(C17="call","Unlimited",MAX(2*E17-D17+J17,J17,0))) -> 6.56 | N17: =IF(B17="Butterfly",IF(AND(J17>0,J17<K17),D17+J17,"n.a."),IF(C17="call",IF(AND(J17>0,J17<K17),D17+J17,"n.a."),IF(AND(K17>J17,2*E17-D17+J17>=0),2*E17-D17+J17,"n.a."))) -> 7206.56 | O17: =IF(B17="Butterfly",IF(AND(J17>0,J17<K17),F17-J17,"n.a."),IF(C17="call",IF(K17>J17,2*E17-D17-J17,"n.a."),IF(AND(J17>0,J17<K17),D17-J17,"n.a."))) -> 7593.44 | P17: =IF(AND(B17="Butterfly",J17>0,J17<K17),L17/J17,"n.a.") -> 29.487805 | Q17: =J17*'Model inputs'!$B$8 -> 656 | R17: Indicative only | S17: 291 | T17: 310
A18: 46281 | B18: Butterfly | C18: put | D18: 7200 | E18: 7400 | F18: 7600 | G18: ='Option source'!B790 -> 550.35 | H18: ='Option source'!B809 -> 677.83 | I18: ='Option source'!B828 -> 857 | J18: =G18-2*H18+IF(B18="Butterfly",I18,0) -> 51.69 | K18: =ABS(E18-D18) -> 200 | L18: =K18-J18 -> 148.31 | M18: =IF(B18="Butterfly",MAX(J18,0),IF(C18="call","Unlimited",MAX(2*E18-D18+J18,J18,0))) -> 51.69 | N18: =IF(B18="Butterfly",IF(AND(J18>0,J18<K18),D18+J18,"n.a."),IF(C18="call",IF(AND(J18>0,J18<K18),D18+J18,"n.a."),IF(AND(K18>J18,2*E18-D18+J18>=0),2*E18-D18+J18,"n.a."))) -> 7251.69 | O18: =IF(B18="Butterfly",IF(AND(J18>0,J18<K18),F18-J18,"n.a."),IF(C18="call",IF(K18>J18,2*E18-D18-J18,"n.a."),IF(AND(J18>0,J18<K18),D18-J18,"n.a."))) -> 7548.31 | P18: =IF(AND(B18="Butterfly",J18>0,J18<K18),L18/J18,"n.a.") -> 2.8692204 | Q18: =J18*'Model inputs'!$B$8 -> 5169 | R18: Indicative only | S18: 785 | T18: 804
A19: 46281 | B19: Butterfly | C19: put | D19: 5800 | E19: 6000 | F19: 6200 | G19: ='Option source'!B657 -> 31.98 | H19: ='Option source'!B676 -> 56.82 | I19: ='Option source'!B695 -> 97.41 | J19: =G19-2*H19+IF(B19="Butterfly",I19,0) -> 15.75 | K19: =ABS(E19-D19) -> 200 | L19: =K19-J19 -> 184.25 | M19: =IF(B19="Butterfly",MAX(J19,0),IF(C19="call","Unlimited",MAX(2*E19-D19+J19,J19,0))) -> 15.75 | N19: =IF(B19="Butterfly",IF(AND(J19>0,J19<K19),D19+J19,"n.a."),IF(C19="call",IF(AND(J19>0,J19<K19),D19+J19,"n.a."),IF(AND(K19>J19,2*E19-D19+J19>=0),2*E19-D19+J19,"n.a."))) -> 5815.75 | O19: =IF(B19="Butterfly",IF(AND(J19>0,J19<K19),F19-J19,"n.a."),IF(C19="call",IF(K19>J19,2*E19-D19-J19,"n.a."),IF(AND(J19>0,J19<K19),D19-J19,"n.a."))) -> 6184.25 | P19: =IF(AND(B19="Butterfly",J19>0,J19<K19),L19/J19,"n.a.") -> 11.698413 | Q19: =J19*'Model inputs'!$B$8 -> 1575 | R19: Indicative only | S19: 652 | T19: 671
A20: 46281 | B20: Butterfly | C20: call | D20: 7400 | E20: 7600 | F20: 7800 | G20: ='Option source'!B315 -> 157.14 | H20: ='Option source'!B334 -> 107.66 | I20: ='Option source'!B353 -> 75.86 | J20: =G20-2*H20+IF(B20="Butterfly",I20,0) -> 17.68 | K20: =ABS(E20-D20) -> 200 | L20: =K20-J20 -> 182.32 | M20: =IF(B20="Butterfly",MAX(J20,0),IF(C20="call","Unlimited",MAX(2*E20-D20+J20,J20,0))) -> 17.68 | N20: =IF(B20="Butterfly",IF(AND(J20>0,J20<K20),D20+J20,"n.a."),IF(C20="call",IF(AND(J20>0,J20<K20),D20+J20,"n.a."),IF(AND(K20>J20,2*E20-D20+J20>=0),2*E20-D20+J20,"n.a."))) -> 7417.68 | O20: =IF(B20="Butterfly",IF(AND(J20>0,J20<K20),F20-J20,"n.a."),IF(C20="call",IF(K20>J20,2*E20-D20-J20,"n.a."),IF(AND(J20>0,J20<K20),D20-J20,"n.a."))) -> 7782.32 | P20: =IF(AND(B20="Butterfly",J20>0,J20<K20),L20/J20,"n.a.") -> 10.312217 | Q20: =J20*'Model inputs'!$B$8 -> 1768 | R20: Indicative only | S20: 310 | T20: 329
A21: 46281 | B21: Butterfly | C21: put | D21: 5600 | E21: 5800 | F21: 6000 | G21: ='Option source'!B638 -> 17.15 | H21: ='Option source'!B657 -> 31.98 | I21: ='Option source'!B676 -> 56.82 | J21: =G21-2*H21+IF(B21="Butterfly",I21,0) -> 10.01 | K21: =ABS(E21-D21) -> 200 | L21: =K21-J21 -> 189.99 | M21: =IF(B21="Butterfly",MAX(J21,0),IF(C21="call","Unlimited",MAX(2*E21-D21+J21,J21,0))) -> 10.01 | N21: =IF(B21="Butterfly",IF(AND(J21>0,J21<K21),D21+J21,"n.a."),IF(C21="call",IF(AND(J21>0,J21<K21),D21+J21,"n.a."),IF(AND(K21>J21,2*E21-D21+J21>=0),2*E21-D21+J21,"n.a."))) -> 5610.01 | O21: =IF(B21="Butterfly",IF(AND(J21>0,J21<K21),F21-J21,"n.a."),IF(C21="call",IF(K21>J21,2*E21-D21-J21,"n.a."),IF(AND(J21>0,J21<K21),D21-J21,"n.a."))) -> 5989.99 | P21: =IF(AND(B21="Butterfly",J21>0,J21<K21),L21/J21,"n.a.") -> 18.98002 | Q21: =J21*'Model inputs'!$B$8 -> 1001 | R21: Indicative only | S21: 633 | T21: 652
A22: 46281 | B22: Butterfly | C22: call | D22: 7600 | E22: 7800 | F22: 8000 | G22: ='Option source'!B334 -> 107.66 | H22: ='Option source'!B353 -> 75.86 | I22: ='Option source'!B372 -> 54.71 | J22: =G22-2*H22+IF(B22="Butterfly",I22,0) -> 10.65 | K22: =ABS(E22-D22) -> 200 | L22: =K22-J22 -> 189.35 | M22: =IF(B22="Butterfly",MAX(J22,0),IF(C22="call","Unlimited",MAX(2*E22-D22+J22,J22,0))) -> 10.65 | N22: =IF(B22="Butterfly",IF(AND(J22>0,J22<K22),D22+J22,"n.a."),IF(C22="call",IF(AND(J22>0,J22<K22),D22+J22,"n.a."),IF(AND(K22>J22,2*E22-D22+J22>=0),2*E22-D22+J22,"n.a."))) -> 7610.65 | O22: =IF(B22="Butterfly",IF(AND(J22>0,J22<K22),F22-J22,"n.a."),IF(C22="call",IF(K22>J22,2*E22-D22-J22,"n.a."),IF(AND(J22>0,J22<K22),D22-J22,"n.a."))) -> 7989.35 | P22: =IF(AND(B22="Butterfly",J22>0,J22<K22),L22/J22,"n.a.") -> 17.779343 | Q22: =J22*'Model inputs'!$B$8 -> 1065 | R22: Indicative only | S22: 329 | T22: 348
A23: 46281 | B23: Butterfly | C23: put | D23: 5400 | E23: 5600 | F23: 5800 | G23: ='Option source'!B619 -> 9.02 | H23: ='Option source'!B638 -> 17.15 | I23: ='Option source'!B657 -> 31.98 | J23: =G23-2*H23+IF(B23="Butterfly",I23,0) -> 6.7 | K23: =ABS(E23-D23) -> 200 | L23: =K23-J23 -> 193.3 | M23: =IF(B23="Butterfly",MAX(J23,0),IF(C23="call","Unlimited",MAX(2*E23-D23+J23,J23,0))) -> 6.7 | N23: =IF(B23="Butterfly",IF(AND(J23>0,J23<K23),D23+J23,"n.a."),IF(C23="call",IF(AND(J23>0,J23<K23),D23+J23,"n.a."),IF(AND(K23>J23,2*E23-D23+J23>=0),2*E23-D23+J23,"n.a."))) -> 5406.7 | O23: =IF(B23="Butterfly",IF(AND(J23>0,J23<K23),F23-J23,"n.a."),IF(C23="call",IF(K23>J23,2*E23-D23-J23,"n.a."),IF(AND(J23>0,J23<K23),D23-J23,"n.a."))) -> 5793.3 | P23: =IF(AND(B23="Butterfly",J23>0,J23<K23),L23/J23,"n.a.") -> 28.850746 | Q23: =J23*'Model inputs'!$B$8 -> 670 | R23: Indicative only | S23: 614 | T23: 633
A24: 46281 | B24: Butterfly | C24: put | D24: 5200 | E24: 5400 | F24: 5600 | G24: ='Option source'!B600 -> 6.01 | H24: ='Option source'!B619 -> 9.02 | I24: ='Option source'!B638 -> 17.15 | J24: =G24-2*H24+IF(B24="Butterfly",I24,0) -> 5.12 | K24: =ABS(E24-D24) -> 200 | L24: =K24-J24 -> 194.88 | M24: =IF(B24="Butterfly",MAX(J24,0),IF(C24="call","Unlimited",MAX(2*E24-D24+J24,J24,0))) -> 5.12 | N24: =IF(B24="Butterfly",IF(AND(J24>0,J24<K24),D24+J24,"n.a."),IF(C24="call",IF(AND(J24>0,J24<K24),D24+J24,"n.a."),IF(AND(K24>J24,2*E24-D24+J24>=0),2*E24-D24+J24,"n.a."))) -> 5205.12 | O24: =IF(B24="Butterfly",IF(AND(J24>0,J24<K24),F24-J24,"n.a."),IF(C24="call",IF(K24>J24,2*E24-D24-J24,"n.a."),IF(AND(J24>0,J24<K24),D24-J24,"n.a."))) -> 5594.88 | P24: =IF(AND(B24="Butterfly",J24>0,J24<K24),L24/J24,"n.a.") -> 38.0625 | Q24: =J24*'Model inputs'!$B$8 -> 512 | R24: Indicative only | S24: 595 | T24: 614
A25: 46281 | B25: Butterfly | C25: call | D25: 8000 | E25: 8300 | F25: 8600 | G25: ='Option source'!B372 -> 54.71 | H25: ='Option source'!B391 -> 32.2 | I25: ='Option source'!B410 -> 17.94 | J25: =G25-2*H25+IF(B25="Butterfly",I25,0) -> 8.25 | K25: =ABS(E25-D25) -> 300 | L25: =K25-J25 -> 291.75 | M25: =IF(B25="Butterfly",MAX(J25,0),IF(C25="call","Unlimited",MAX(2*E25-D25+J25,J25,0))) -> 8.25 | N25: =IF(B25="Butterfly",IF(AND(J25>0,J25<K25),D25+J25,"n.a."),IF(C25="call",IF(AND(J25>0,J25<K25),D25+J25,"n.a."),IF(AND(K25>J25,2*E25-D25+J25>=0),2*E25-D25+J25,"n.a."))) -> 8008.25 | O25: =IF(B25="Butterfly",IF(AND(J25>0,J25<K25),F25-J25,"n.a."),IF(C25="call",IF(K25>J25,2*E25-D25-J25,"n.a."),IF(AND(J25>0,J25<K25),D25-J25,"n.a."))) -> 8591.75 | P25: =IF(AND(B25="Butterfly",J25>0,J25<K25),L25/J25,"n.a.") -> 35.363636 | Q25: =J25*'Model inputs'!$B$8 -> 825 | R25: Indicative only | S25: 367 | T25: 386
A26: 46281 | B26: Butterfly | C26: put | D26: 5000 | E26: 5200 | F26: 5400 | G26: ='Option source'!B581 -> 3.18 | H26: ='Option source'!B600 -> 6.01 | I26: ='Option source'!B619 -> 9.02 | J26: =G26-2*H26+IF(B26="Butterfly",I26,0) -> 0.18 | K26: =ABS(E26-D26) -> 200 | L26: =K26-J26 -> 199.82 | M26: =IF(B26="Butterfly",MAX(J26,0),IF(C26="call","Unlimited",MAX(2*E26-D26+J26,J26,0))) -> 0.18 | N26: =IF(B26="Butterfly",IF(AND(J26>0,J26<K26),D26+J26,"n.a."),IF(C26="call",IF(AND(J26>0,J26<K26),D26+J26,"n.a."),IF(AND(K26>J26,2*E26-D26+J26>=0),2*E26-D26+J26,"n.a."))) -> 5000.18 | O26: =IF(B26="Butterfly",IF(AND(J26>0,J26<K26),F26-J26,"n.a."),IF(C26="call",IF(K26>J26,2*E26-D26-J26,"n.a."),IF(AND(J26>0,J26<K26),D26-J26,"n.a."))) -> 5399.82 | P26: =IF(AND(B26="Butterfly",J26>0,J26<K26),L26/J26,"n.a.") -> 1110.1111 | Q26: =J26*'Model inputs'!$B$8 -> 18 | R26: Indicative only | S26: 576 | T26: 595
A27: 46281 | B27: Butterfly | C27: put | D27: 4800 | E27: 5000 | F27: 5200 | G27: ='Option source'!B562 -> 1.93 | H27: ='Option source'!B581 -> 3.18 | I27: ='Option source'!B600 -> 6.01 | J27: =G27-2*H27+IF(B27="Butterfly",I27,0) -> 1.58 | K27: =ABS(E27-D27) -> 200 | L27: =K27-J27 -> 198.42 | M27: =IF(B27="Butterfly",MAX(J27,0),IF(C27="call","Unlimited",MAX(2*E27-D27+J27,J27,0))) -> 1.58 | N27: =IF(B27="Butterfly",IF(AND(J27>0,J27<K27),D27+J27,"n.a."),IF(C27="call",IF(AND(J27>0,J27<K27),D27+J27,"n.a."),IF(AND(K27>J27,2*E27-D27+J27>=0),2*E27-D27+J27,"n.a."))) -> 4801.58 | O27: =IF(B27="Butterfly",IF(AND(J27>0,J27<K27),F27-J27,"n.a."),IF(C27="call",IF(K27>J27,2*E27-D27-J27,"n.a."),IF(AND(J27>0,J27<K27),D27-J27,"n.a."))) -> 5198.42 | P27: =IF(AND(B27="Butterfly",J27>0,J27<K27),L27/J27,"n.a.") -> 125.58228 | Q27: =J27*'Model inputs'!$B$8 -> 158 | R27: Indicative only | S27: 557 | T27: 576
A28: 46281 | B28: Butterfly | C28: call | D28: 8300 | E28: 8600 | F28: 8900 | G28: ='Option source'!B391 -> 32.2 | H28: ='Option source'!B410 -> 17.94 | I28: ='Option source'!B429 -> 9.99 | J28: =G28-2*H28+IF(B28="Butterfly",I28,0) -> 6.31 | K28: =ABS(E28-D28) -> 300 | L28: =K28-J28 -> 293.69 | M28: =IF(B28="Butterfly",MAX(J28,0),IF(C28="call","Unlimited",MAX(2*E28-D28+J28,J28,0))) -> 6.31 | N28: =IF(B28="Butterfly",IF(AND(J28>0,J28<K28),D28+J28,"n.a."),IF(C28="call",IF(AND(J28>0,J28<K28),D28+J28,"n.a."),IF(AND(K28>J28,2*E28-D28+J28>=0),2*E28-D28+J28,"n.a."))) -> 8306.31 | O28: =IF(B28="Butterfly",IF(AND(J28>0,J28<K28),F28-J28,"n.a."),IF(C28="call",IF(K28>J28,2*E28-D28-J28,"n.a."),IF(AND(J28>0,J28<K28),D28-J28,"n.a."))) -> 8893.69 | P28: =IF(AND(B28="Butterfly",J28>0,J28<K28),L28/J28,"n.a.") -> 46.543582 | Q28: =J28*'Model inputs'!$B$8 -> 631 | R28: Indicative only | S28: 386 | T28: 405
A29: 46281 | B29: Butterfly | C29: put | D29: 4600 | E29: 4800 | F29: 5000 | G29: ='Option source'!B543 -> 1.62 | H29: ='Option source'!B562 -> 1.93 | I29: ='Option source'!B581 -> 3.18 | J29: =G29-2*H29+IF(B29="Butterfly",I29,0) -> 0.94 | K29: =ABS(E29-D29) -> 200 | L29: =K29-J29 -> 199.06 | M29: =IF(B29="Butterfly",MAX(J29,0),IF(C29="call","Unlimited",MAX(2*E29-D29+J29,J29,0))) -> 0.94 | N29: =IF(B29="Butterfly",IF(AND(J29>0,J29<K29),D29+J29,"n.a."),IF(C29="call",IF(AND(J29>0,J29<K29),D29+J29,"n.a."),IF(AND(K29>J29,2*E29-D29+J29>=0),2*E29-D29+J29,"n.a."))) -> 4600.94 | O29: =IF(B29="Butterfly",IF(AND(J29>0,J29<K29),F29-J29,"n.a."),IF(C29="call",IF(K29>J29,2*E29-D29-J29,"n.a."),IF(AND(J29>0,J29<K29),D29-J29,"n.a."))) -> 4999.06 | P29: =IF(AND(B29="Butterfly",J29>0,J29<K29),L29/J29,"n.a.") -> 211.76596 | Q29: =J29*'Model inputs'!$B$8 -> 94 | R29: Indicative only | S29: 538 | T29: 557
A30: 46281 | B30: Butterfly | C30: call | D30: 8600 | E30: 8900 | F30: 9200 | G30: ='Option source'!B410 -> 17.94 | H30: ='Option source'!B429 -> 9.99 | I30: ='Option source'!B448 -> 3.53 | J30: =G30-2*H30+IF(B30="Butterfly",I30,0) -> 1.49 | K30: =ABS(E30-D30) -> 300 | L30: =K30-J30 -> 298.51 | M30: =IF(B30="Butterfly",MAX(J30,0),IF(C30="call","Unlimited",MAX(2*E30-D30+J30,J30,0))) -> 1.49 | N30: =IF(B30="Butterfly",IF(AND(J30>0,J30<K30),D30+J30,"n.a."),IF(C30="call",IF(AND(J30>0,J30<K30),D30+J30,"n.a."),IF(AND(K30>J30,2*E30-D30+J30>=0),2*E30-D30+J30,"n.a."))) -> 8601.49 | O30: =IF(B30="Butterfly",IF(AND(J30>0,J30<K30),F30-J30,"n.a."),IF(C30="call",IF(K30>J30,2*E30-D30-J30,"n.a."),IF(AND(J30>0,J30<K30),D30-J30,"n.a."))) -> 9198.51 | P30: =IF(AND(B30="Butterfly",J30>0,J30<K30),L30/J30,"n.a.") -> 200.34228 | Q30: =J30*'Model inputs'!$B$8 -> 149 | R30: Indicative only | S30: 405 | T30: 424
A31: 46281 | B31: Butterfly | C31: put | D31: 4200 | E31: 4400 | F31: 4600 | G31: ='Option source'!B505 -> 1.21 | H31: ='Option source'!B524 -> 0.91 | I31: ='Option source'!B543 -> 1.62 | J31: =G31-2*H31+IF(B31="Butterfly",I31,0) -> 1.01 | K31: =ABS(E31-D31) -> 200 | L31: =K31-J31 -> 198.99 | M31: =IF(B31="Butterfly",MAX(J31,0),IF(C31="call","Unlimited",MAX(2*E31-D31+J31,J31,0))) -> 1.01 | N31: =IF(B31="Butterfly",IF(AND(J31>0,J31<K31),D31+J31,"n.a."),IF(C31="call",IF(AND(J31>0,J31<K31),D31+J31,"n.a."),IF(AND(K31>J31,2*E31-D31+J31>=0),2*E31-D31+J31,"n.a."))) -> 4201.01 | O31: =IF(B31="Butterfly",IF(AND(J31>0,J31<K31),F31-J31,"n.a."),IF(C31="call",IF(K31>J31,2*E31-D31-J31,"n.a."),IF(AND(J31>0,J31<K31),D31-J31,"n.a."))) -> 4598.99 | P31: =IF(AND(B31="Butterfly",J31>0,J31<K31),L31/J31,"n.a.") -> 197.0198 | Q31: =J31*'Model inputs'!$B$8 -> 101 | R31: Indicative only | S31: 500 | T31: 519
A32: 46281 | B32: Butterfly | C32: call | D32: 8900 | E32: 9200 | F32: 9500 | G32: ='Option source'!B429 -> 9.99 | H32: ='Option source'!B448 -> 3.53 | I32: ='Option source'!B467 -> 3.44 | J32: =G32-2*H32+IF(B32="Butterfly",I32,0) -> 6.37 | K32: =ABS(E32-D32) -> 300 | L32: =K32-J32 -> 293.63 | M32: =IF(B32="Butterfly",MAX(J32,0),IF(C32="call","Unlimited",MAX(2*E32-D32+J32,J32,0))) -> 6.37 | N32: =IF(B32="Butterfly",IF(AND(J32>0,J32<K32),D32+J32,"n.a."),IF(C32="call",IF(AND(J32>0,J32<K32),D32+J32,"n.a."),IF(AND(K32>J32,2*E32-D32+J32>=0),2*E32-D32+J32,"n.a."))) -> 8906.37 | O32: =IF(B32="Butterfly",IF(AND(J32>0,J32<K32),F32-J32,"n.a."),IF(C32="call",IF(K32>J32,2*E32-D32-J32,"n.a."),IF(AND(J32>0,J32<K32),D32-J32,"n.a."))) -> 9493.63 | P32: =IF(AND(B32="Butterfly",J32>0,J32<K32),L32/J32,"n.a.") -> 46.095761 | Q32: =J32*'Model inputs'!$B$8 -> 637 | R32: Indicative only | S32: 424 | T32: 443
A33: 46281 | B33: Butterfly | C33: call | D33: 6200 | E33: 6400 | F33: 6600 | G33: ='Option source'!B201 -> 704.74 | H33: ='Option source'!B220 -> 616.1 | I33: ='Option source'!B239 -> 478.22 | J33: =G33-2*H33+IF(B33="Butterfly",I33,0) -> -49.24 | K33: =ABS(E33-D33) -> 200 | L33: =K33-J33 -> 249.24 | M33: =IF(B33="Butterfly",MAX(J33,0),IF(C33="call","Unlimited",MAX(2*E33-D33+J33,J33,0))) -> 0 | N33: =IF(B33="Butterfly",IF(AND(J33>0,J33<K33),D33+J33,"n.a."),IF(C33="call",IF(AND(J33>0,J33<K33),D33+J33,"n.a."),IF(AND(K33>J33,2*E33-D33+J33>=0),2*E33-D33+J33,"n.a."))) -> n.a. | O33: =IF(B33="Butterfly",IF(AND(J33>0,J33<K33),F33-J33,"n.a."),IF(C33="call",IF(K33>J33,2*E33-D33-J33,"n.a."),IF(AND(J33>0,J33<K33),D33-J33,"n.a."))) -> n.a. | P33: =IF(AND(B33="Butterfly",J33>0,J33<K33),L33/J33,"n.a.") -> n.a. | Q33: =J33*'Model inputs'!$B$8 -> -4924 | R33: Outside standard debit bounds | S33: 196 | T33: 215
A34: 46281 | B34: Butterfly | C34: call | D34: 6000 | E34: 6200 | F34: 6400 | G34: ='Option source'!B182 -> 916.41 | H34: ='Option source'!B201 -> 704.74 | I34: ='Option source'!B220 -> 616.1 | J34: =G34-2*H34+IF(B34="Butterfly",I34,0) -> 123.03 | K34: =ABS(E34-D34) -> 200 | L34: =K34-J34 -> 76.97 | M34: =IF(B34="Butterfly",MAX(J34,0),IF(C34="call","Unlimited",MAX(2*E34-D34+J34,J34,0))) -> 123.03 | N34: =IF(B34="Butterfly",IF(AND(J34>0,J34<K34),D34+J34,"n.a."),IF(C34="call",IF(AND(J34>0,J34<K34),D34+J34,"n.a."),IF(AND(K34>J34,2*E34-D34+J34>=0),2*E34-D34+J34,"n.a."))) -> 6123.03 | O34: =IF(B34="Butterfly",IF(AND(J34>0,J34<K34),F34-J34,"n.a."),IF(C34="call",IF(K34>J34,2*E34-D34-J34,"n.a."),IF(AND(J34>0,J34<K34),D34-J34,"n.a."))) -> 6276.97 | P34: =IF(AND(B34="Butterfly",J34>0,J34<K34),L34/J34,"n.a.") -> 0.62561977 | Q34: =J34*'Model inputs'!$B$8 -> 12303 | R34: Flagged leg data | S34: 177 | T34: 196
